2021/01/19 09:49:22 : customers_errors 1: Traceback (most recent call last):
  File "/opt/lampp/htdocs/v32/cartmigration/controllers/migration.py", line 1036, in migration
    convert = fn_convert_export(main, ext)
  File "/opt/lampp/htdocs/v32/cartmigration/models/cart/custom.py", line 928, in convert_customer_export
    customer_data['username'] = customer['login']
KeyError: 'login'

2021/01/19 09:49:22 : customers_errors 3: Traceback (most recent call last):
  File "/opt/lampp/htdocs/v32/cartmigration/controllers/migration.py", line 1036, in migration
    convert = fn_convert_export(main, ext)
  File "/opt/lampp/htdocs/v32/cartmigration/models/cart/custom.py", line 928, in convert_customer_export
    customer_data['username'] = customer['login']
KeyError: 'login'

