2021/01/16 13:59:12 : categories_errors 2: Traceback (most recent call last):
  File "/opt/lampp/htdocs/v32/cartmigration/controllers/migration.py", line 1036, in migration
    convert = fn_convert_export(main, ext)
  File "/opt/lampp/htdocs/v32/cartmigration/models/cart/custom.py", line 383, in convert_category_export
    category_data['id'] = category['id']
KeyError: 'id'

2021/01/16 13:59:16 : categories_errors 3: Traceback (most recent call last):
  File "/opt/lampp/htdocs/v32/cartmigration/controllers/migration.py", line 1036, in migration
    convert = fn_convert_export(main, ext)
  File "/opt/lampp/htdocs/v32/cartmigration/models/cart/custom.py", line 383, in convert_category_export
    category_data['id'] = category['id']
KeyError: 'id'

2021/01/16 13:59:21 : categories_errors 4: Traceback (most recent call last):
  File "/opt/lampp/htdocs/v32/cartmigration/controllers/migration.py", line 1036, in migration
    convert = fn_convert_export(main, ext)
  File "/opt/lampp/htdocs/v32/cartmigration/models/cart/custom.py", line 383, in convert_category_export
    category_data['id'] = category['id']
KeyError: 'id'

