2021/01/18 10:29:51 : categories_errors 2: Traceback (most recent call last):
  File "/opt/lampp/htdocs/v32/cartmigration/controllers/migration.py", line 1036, in migration
    convert = fn_convert_export(main, ext)
  File "/opt/lampp/htdocs/v32/cartmigration/models/cart/custom.py", line 400, in convert_category_export
    category_data['name'] = category_description['categories_name']
KeyError: 'name'

2021/01/18 10:29:51 : categories_errors 3: Traceback (most recent call last):
  File "/opt/lampp/htdocs/v32/cartmigration/controllers/migration.py", line 1036, in migration
    convert = fn_convert_export(main, ext)
  File "/opt/lampp/htdocs/v32/cartmigration/models/cart/custom.py", line 400, in convert_category_export
    category_data['name'] = category_description['categories_name']
KeyError: 'name'

2021/01/18 10:29:51 : categories_errors 4: Traceback (most recent call last):
  File "/opt/lampp/htdocs/v32/cartmigration/controllers/migration.py", line 1036, in migration
    convert = fn_convert_export(main, ext)
  File "/opt/lampp/htdocs/v32/cartmigration/models/cart/custom.py", line 400, in convert_category_export
    category_data['name'] = category_description['categories_name']
KeyError: 'name'

