2021/01/20 10:27:05 : orders_errors 1: Traceback (most recent call last):
  File "/opt/lampp/htdocs/v32/cartmigration/controllers/migration.py", line 1036, in migration
    convert = fn_convert_export(main, ext)
  File "/opt/lampp/htdocs/v32/cartmigration/models/cart/custom.py", line 1209, in convert_order_export
    order_products = get_list_from_list_by_field(orders_ext['data']['orders_products'], 'orders_id', order['id'])
KeyError: 'id'

2021/01/20 10:27:07 : orders_errors 2: Traceback (most recent call last):
  File "/opt/lampp/htdocs/v32/cartmigration/controllers/migration.py", line 1036, in migration
    convert = fn_convert_export(main, ext)
  File "/opt/lampp/htdocs/v32/cartmigration/models/cart/custom.py", line 1209, in convert_order_export
    order_products = get_list_from_list_by_field(orders_ext['data']['orders_products'], 'orders_id', order['id'])
KeyError: 'id'

