2021/01/18 15:23:22 : products_errors 9: Traceback (most recent call last):
  File "/opt/lampp/htdocs/v32/cartmigration/controllers/migration.py", line 1036, in migration
    convert = fn_convert_export(main, ext)
  File "/opt/lampp/htdocs/v32/cartmigration/models/cart/custom.py", line 534, in convert_product_export
    product_data['id'] = product['id']
KeyError: 'id'

