2021/01/20 10:50:20 : orders_errors 1: Traceback (most recent call last):
  File "/opt/lampp/htdocs/v32/cartmigration/controllers/migration.py", line 1036, in migration
    convert = fn_convert_export(main, ext)
  File "/opt/lampp/htdocs/v32/cartmigration/models/cart/custom.py", line 1219, in convert_order_export
    order_item['product']['id'] = order_product['orders_product_id']
KeyError: 'orders_product_id'

2021/01/20 10:50:26 : orders_errors 2: Traceback (most recent call last):
  File "/opt/lampp/htdocs/v32/cartmigration/controllers/migration.py", line 1036, in migration
    convert = fn_convert_export(main, ext)
  File "/opt/lampp/htdocs/v32/cartmigration/models/cart/custom.py", line 1219, in convert_order_export
    order_item['product']['id'] = order_product['orders_product_id']
KeyError: 'orders_product_id'

