2021/01/18 09:42:34 : categories_errors 2: Traceback (most recent call last):
  File "/opt/lampp/htdocs/v32/cartmigration/controllers/migration.py", line 1036, in migration
    convert = fn_convert_export(main, ext)
  File "/opt/lampp/htdocs/v32/cartmigration/models/cart/custom.py", line 387, in convert_category_export
    img = get_row_from_list_by_field(categories_ext['data']['cate_imgs'],'cat_id', category['id'])
KeyError: 'cate_imgs'

