2021/01/21 13:43:22 : orders_errors 1: Traceback (most recent call last):
  File "/opt/lampp/htdocs/v32/cartmigration/controllers/migration.py", line 1036, in migration
    convert = fn_convert_export(main, ext)
  File "/opt/lampp/htdocs/v32/cartmigration/models/cart/custom.py", line 1109, in convert_order_export
    order_data['created_at'] = datetime.order['date_purchased']
AttributeError: type object 'datetime.datetime' has no attribute 'order'

2021/01/21 13:43:22 : orders_errors 2: Traceback (most recent call last):
  File "/opt/lampp/htdocs/v32/cartmigration/controllers/migration.py", line 1036, in migration
    convert = fn_convert_export(main, ext)
  File "/opt/lampp/htdocs/v32/cartmigration/models/cart/custom.py", line 1109, in convert_order_export
    order_data['created_at'] = datetime.order['date_purchased']
AttributeError: type object 'datetime.datetime' has no attribute 'order'

2021/01/21 13:43:22 : orders_errors 3: Traceback (most recent call last):
  File "/opt/lampp/htdocs/v32/cartmigration/controllers/migration.py", line 1036, in migration
    convert = fn_convert_export(main, ext)
  File "/opt/lampp/htdocs/v32/cartmigration/models/cart/custom.py", line 1109, in convert_order_export
    order_data['created_at'] = datetime.order['date_purchased']
AttributeError: type object 'datetime.datetime' has no attribute 'order'

2021/01/21 13:43:22 : orders_errors 4: Traceback (most recent call last):
  File "/opt/lampp/htdocs/v32/cartmigration/controllers/migration.py", line 1036, in migration
    convert = fn_convert_export(main, ext)
  File "/opt/lampp/htdocs/v32/cartmigration/models/cart/custom.py", line 1109, in convert_order_export
    order_data['created_at'] = datetime.order['date_purchased']
AttributeError: type object 'datetime.datetime' has no attribute 'order'

2021/01/21 13:43:22 : orders_errors 5: Traceback (most recent call last):
  File "/opt/lampp/htdocs/v32/cartmigration/controllers/migration.py", line 1036, in migration
    convert = fn_convert_export(main, ext)
  File "/opt/lampp/htdocs/v32/cartmigration/models/cart/custom.py", line 1109, in convert_order_export
    order_data['created_at'] = datetime.order['date_purchased']
AttributeError: type object 'datetime.datetime' has no attribute 'order'

2021/01/21 13:43:22 : orders_errors 6: Traceback (most recent call last):
  File "/opt/lampp/htdocs/v32/cartmigration/controllers/migration.py", line 1036, in migration
    convert = fn_convert_export(main, ext)
  File "/opt/lampp/htdocs/v32/cartmigration/models/cart/custom.py", line 1109, in convert_order_export
    order_data['created_at'] = datetime.order['date_purchased']
AttributeError: type object 'datetime.datetime' has no attribute 'order'

2021/01/21 13:43:22 : orders_errors 7: Traceback (most recent call last):
  File "/opt/lampp/htdocs/v32/cartmigration/controllers/migration.py", line 1036, in migration
    convert = fn_convert_export(main, ext)
  File "/opt/lampp/htdocs/v32/cartmigration/models/cart/custom.py", line 1109, in convert_order_export
    order_data['created_at'] = datetime.order['date_purchased']
AttributeError: type object 'datetime.datetime' has no attribute 'order'

2021/01/21 13:43:22 : orders_errors 8: Traceback (most recent call last):
  File "/opt/lampp/htdocs/v32/cartmigration/controllers/migration.py", line 1036, in migration
    convert = fn_convert_export(main, ext)
  File "/opt/lampp/htdocs/v32/cartmigration/models/cart/custom.py", line 1109, in convert_order_export
    order_data['created_at'] = datetime.order['date_purchased']
AttributeError: type object 'datetime.datetime' has no attribute 'order'

